<?xml version="1.0" encoding="UTF-8"?>
<!-- Generated by org.testng.reporters.JUnitReportReporter -->
<testsuite hostname="DESKTOP-E69K95O" name="sauceDemoTests.loginValidationV2" tests="4" failures="1" timestamp="12 Jun 2022 16:17:00 GMT" time="13.996" errors="0">
  <testcase name="performanceGlitchUserLogin" time="7.487" classname="sauceDemoTests.loginValidationV2">
    <failure type="java.lang.AssertionError" message="expected [https://www.saucedemo.com/inventor.html] but found [https://www.saucedemo.com/inventory.html]">
      <![CDATA[java.lang.AssertionError: expected [https://www.saucedemo.com/inventor.html] but found [https://www.saucedemo.com/inventory.html]
	at org.testng.Assert.fail(Assert.java:94)
	at org.testng.Assert.failNotEquals(Assert.java:496)
	at org.testng.Assert.assertEquals(Assert.java:125)
	at org.testng.Assert.assertEquals(Assert.java:178)
	at org.testng.Assert.assertEquals(Assert.java:188)
	at sauceDemoTests.loginValidationV2.performanceGlitchUserLogin(loginValidationV2.java:126)
	at sun.reflect.NativeMethodAccessorImpl.invoke0(Native Method)
	at sun.reflect.NativeMethodAccessorImpl.invoke(Unknown Source)
	at sun.reflect.DelegatingMethodAccessorImpl.invoke(Unknown Source)
	at java.lang.reflect.Method.invoke(Unknown Source)
	at org.testng.internal.MethodInvocationHelper.invokeMethod(MethodInvocationHelper.java:85)
	at org.testng.internal.Invoker.invokeMethod(Invoker.java:639)
	at org.testng.internal.Invoker.invokeTestMethod(Invoker.java:816)
	at org.testng.internal.Invoker.invokeTestMethods(Invoker.java:1124)
	at org.testng.internal.TestMethodWorker.invokeTestMethods(TestMethodWorker.java:125)
	at org.testng.internal.TestMethodWorker.run(TestMethodWorker.java:108)
	at org.testng.TestRunner.privateRun(TestRunner.java:774)
	at org.testng.TestRunner.run(TestRunner.java:624)
	at org.testng.SuiteRunner.runTest(SuiteRunner.java:359)
	at org.testng.SuiteRunner.runSequentially(SuiteRunner.java:354)
	at org.testng.SuiteRunner.privateRun(SuiteRunner.java:312)
	at org.testng.SuiteRunner.run(SuiteRunner.java:261)
	at org.testng.SuiteRunnerWorker.runSuite(SuiteRunnerWorker.java:52)
	at org.testng.SuiteRunnerWorker.run(SuiteRunnerWorker.java:86)
	at org.testng.TestNG.runSuitesSequentially(TestNG.java:1215)
	at org.testng.TestNG.runSuitesLocally(TestNG.java:1140)
	at org.testng.TestNG.run(TestNG.java:1048)
	at org.testng.remote.AbstractRemoteTestNG.run(AbstractRemoteTestNG.java:115)
	at org.testng.remote.RemoteTestNG.initAndRun(RemoteTestNG.java:251)
	at org.testng.remote.RemoteTestNG.main(RemoteTestNG.java:77)
]]>
    </failure>
  </testcase> <!-- performanceGlitchUserLogin -->
  <testcase name="lockedOutUserLogin" time="2.358" classname="sauceDemoTests.loginValidationV2"/>
  <testcase name="problemUserLogin" time="2.630" classname="sauceDemoTests.loginValidationV2"/>
  <testcase name="standardUserLogin" time="1.521" classname="sauceDemoTests.loginValidationV2"/>
</testsuite> <!-- sauceDemoTests.loginValidationV2 -->
